<?xml version="1.0" encoding="UTF-8"?>
<!-- Generated by org.testng.reporters.JUnitReportReporter -->
<testsuite hostname="KAITLYN" failures="2" tests="6" name="dsAlgoTests.ArrayPageTest" time="48.967" errors="0" timestamp="2025-05-24T00:44:22 CDT" skipped="4">
  <testcase classname="dsAlgoTests.ArrayPageTest" name="submitInvalidCodeSqrsOfSortedArrayQtn" time="7.934">
    <failure message="expected [Error occurred during submission] but found [ No tests were collected]" type="java.lang.AssertionError">
      <![CDATA[java.lang.AssertionError: expected [Error occurred during submission] but found [ No tests were collected]
at org.testng.Assert.fail(Assert.java:111)
at org.testng.Assert.failNotEquals(Assert.java:1590)
at org.testng.Assert.assertEqualsImpl(Assert.java:150)
at org.testng.Assert.assertEquals(Assert.java:132)
at org.testng.Assert.assertEquals(Assert.java:656)
at org.testng.Assert.assertEquals(Assert.java:666)
at dsAlgoTests.ArrayPageTest.submitInvalidCodeSqrsOfSortedArrayQtn(ArrayPageTest.java:308)
at java.base/jdk.internal.reflect.DirectMethodHandleAccessor.invoke(DirectMethodHandleAccessor.java:103)
at java.base/java.lang.reflect.Method.invoke(Method.java:580)
at org.testng.internal.invokers.MethodInvocationHelper.invokeMethod(MethodInvocationHelper.java:141)
at org.testng.internal.invokers.TestInvoker.invokeMethod(TestInvoker.java:687)
at org.testng.internal.invokers.TestInvoker.retryFailed(TestInvoker.java:269)
at org.testng.internal.invokers.MethodRunner.runInSequence(MethodRunner.java:76)
at org.testng.internal.invokers.TestInvoker$MethodInvocationAgent.invoke(TestInvoker.java:995)
at org.testng.internal.invokers.TestInvoker.invokeTestMethods(TestInvoker.java:203)
at org.testng.internal.invokers.TestMethodWorker.invokeTestMethods(TestMethodWorker.java:154)
at org.testng.internal.invokers.TestMethodWorker.run(TestMethodWorker.java:134)
at java.base/java.util.concurrent.Executors$RunnableAdapter.call(Executors.java:572)
at java.base/java.util.concurrent.FutureTask.run(FutureTask.java:317)
at org.testng.internal.thread.graph.TestNGFutureTask.run(TestNGFutureTask.java:22)
at java.base/java.util.concurrent.ThreadPoolExecutor.runWorker(ThreadPoolExecutor.java:1144)
at java.base/java.util.concurrent.ThreadPoolExecutor$Worker.run(ThreadPoolExecutor.java:642)
at java.base/java.lang.Thread.run(Thread.java:1583)
]]>
    </failure>
  </testcase> <!-- submitInvalidCodeSqrsOfSortedArrayQtn -->
  <testcase classname="dsAlgoTests.ArrayPageTest" name="submitInvalidCodeSqrsOfSortedArrayQtn" time="8.134">
    <skipped/>
  </testcase> <!-- submitInvalidCodeSqrsOfSortedArrayQtn -->
  <testcase classname="dsAlgoTests.ArrayPageTest" name="submitInvalidCodeSqrsOfSortedArrayQtn" time="8.301">
    <failure message="expected [Error occurred during submission] but found [ No tests were collected]" type="java.lang.AssertionError">
      <![CDATA[java.lang.AssertionError: expected [Error occurred during submission] but found [ No tests were collected]
at org.testng.Assert.fail(Assert.java:111)
at org.testng.Assert.failNotEquals(Assert.java:1590)
at org.testng.Assert.assertEqualsImpl(Assert.java:150)
at org.testng.Assert.assertEquals(Assert.java:132)
at org.testng.Assert.assertEquals(Assert.java:656)
at org.testng.Assert.assertEquals(Assert.java:666)
at dsAlgoTests.ArrayPageTest.submitInvalidCodeSqrsOfSortedArrayQtn(ArrayPageTest.java:308)
at java.base/jdk.internal.reflect.DirectMethodHandleAccessor.invoke(DirectMethodHandleAccessor.java:103)
at java.base/java.lang.reflect.Method.invoke(Method.java:580)
at org.testng.internal.invokers.MethodInvocationHelper.invokeMethod(MethodInvocationHelper.java:141)
at org.testng.internal.invokers.TestInvoker.invokeMethod(TestInvoker.java:687)
at org.testng.internal.invokers.TestInvoker.retryFailed(TestInvoker.java:269)
at org.testng.internal.invokers.MethodRunner.runInSequence(MethodRunner.java:76)
at org.testng.internal.invokers.TestInvoker$MethodInvocationAgent.invoke(TestInvoker.java:995)
at org.testng.internal.invokers.TestInvoker.invokeTestMethods(TestInvoker.java:203)
at org.testng.internal.invokers.TestMethodWorker.invokeTestMethods(TestMethodWorker.java:154)
at org.testng.internal.invokers.TestMethodWorker.run(TestMethodWorker.java:134)
at java.base/java.util.concurrent.Executors$RunnableAdapter.call(Executors.java:572)
at java.base/java.util.concurrent.FutureTask.run(FutureTask.java:317)
at org.testng.internal.thread.graph.TestNGFutureTask.run(TestNGFutureTask.java:22)
at java.base/java.util.concurrent.ThreadPoolExecutor.runWorker(ThreadPoolExecutor.java:1144)
at java.base/java.util.concurrent.ThreadPoolExecutor$Worker.run(ThreadPoolExecutor.java:642)
at java.base/java.lang.Thread.run(Thread.java:1583)
]]>
    </failure>
  </testcase> <!-- submitInvalidCodeSqrsOfSortedArrayQtn -->
  <testcase classname="dsAlgoTests.ArrayPageTest" name="submitInvalidCodeSqrsOfSortedArrayQtn" time="8.534">
    <skipped/>
  </testcase> <!-- submitInvalidCodeSqrsOfSortedArrayQtn -->
  <testcase classname="dsAlgoTests.ArrayPageTest" name="submitInvalidCodeSqrsOfSortedArrayQtn" time="8.128">
    <skipped/>
  </testcase> <!-- submitInvalidCodeSqrsOfSortedArrayQtn -->
  <testcase classname="dsAlgoTests.ArrayPageTest" name="submitInvalidCodeSqrsOfSortedArrayQtn" time="7.936">
    <skipped/>
  </testcase> <!-- submitInvalidCodeSqrsOfSortedArrayQtn -->
</testsuite> <!-- dsAlgoTests.ArrayPageTest -->
